<?xml version="1.0" encoding="utf-8"?>
<!-- This URDF was automatically created by SolidWorks to URDF Exporter! Originally created by Stephen Brawner (brawner@gmail.com) 
     Commit Version: 1.6.0-4-g7f85cfe  Build Version: 1.6.7995.38578
     For more information, please see http://wiki.ros.org/sw_urdf_exporter -->
<robot
  name="Robot-0411-1400">
  <link
    name="Body">
    <inertial>
      <origin
        xyz="-0.0269364590999195 0.0750000000000001 -0.0333020701103129"
        rpy="0 0 0" />
      <mass
        value="0.259687822807211" />
      <inertia
        ixx="0.000263883767567918"
        ixy="1.03789660179479E-19"
        ixz="2.83874959864717E-05"
        iyy="0.00029022151243818"
        iyz="-1.14819286467261E-19"
        izz="0.000304338639837751" />
    </inertial>
    <visual>
      <origin
        xyz="0 0 0"
        rpy="0 0 0" />
      <geometry>
        <mesh
          filename="package://Robot-0411-1400/meshes/Body.STL" />
      </geometry>
      <material
        name="">
        <color
          rgba="0.792156862745098 0.819607843137255 0.933333333333333 1" />
      </material>
    </visual>
    <collision>
      <origin
        xyz="0 0 0"
        rpy="0 0 0" />
      <geometry>
        <mesh
          filename="package://Robot-0411-1400/meshes/Body.STL" />
      </geometry>
    </collision>
  </link>
  <link
    name="Wheel_1">
    <inertial>
      <origin
        xyz="-1.38777878078145E-17 1.89387097171004E-17 0"
        rpy="0 0 0" />
      <mass
        value="0.0981527452118755" />
      <inertia
        ixx="7.13246475399757E-05"
        ixy="-1.04144755691584E-20"
        ixz="5.2206685043356E-20"
        iyy="0.00013687545343136"
        iyz="2.41289959932004E-21"
        izz="7.13246475399756E-05" />
    </inertial>
    <visual>
      <origin
        xyz="0 0 0"
        rpy="0 0 0" />
      <geometry>
        <mesh
          filename="package://Robot-0411-1400/meshes/Wheel_1.STL" />
      </geometry>
      <material
        name="">
        <color
          rgba="0.792156862745098 0.819607843137255 0.933333333333333 1" />
      </material>
    </visual>
    <collision>
      <origin
        xyz="0 0 0"
        rpy="0 0 0" />
      <geometry>
        <mesh
          filename="package://Robot-0411-1400/meshes/Wheel_1.STL" />
      </geometry>
    </collision>
  </link>
  <joint
    name="Wheel_1"
    type="continuous">
    <origin
      xyz="-0.025708 0 -0.14522"
      rpy="0 0 0" />
    <parent
      link="Body" />
    <child
      link="Wheel_1" />
    <axis
      xyz="0 -1 0" />
  </joint>
  <link
    name="Wheel_2">
    <inertial>
      <origin
        xyz="8.46545056276682E-16 0.01 0"
        rpy="0 0 0" />
      <mass
        value="0.0981527452118754" />
      <inertia
        ixx="7.13246475399757E-05"
        ixy="1.19369642570729E-20"
        ixz="5.10267040368649E-20"
        iyy="0.00013687545343136"
        iyz="-2.66693715768763E-21"
        izz="7.13246475399756E-05" />
    </inertial>
    <visual>
      <origin
        xyz="0 0 0"
        rpy="0 0 0" />
      <geometry>
        <mesh
          filename="package://Robot-0411-1400/meshes/Wheel_2.STL" />
      </geometry>
      <material
        name="">
        <color
          rgba="0.792156862745098 0.819607843137255 0.933333333333333 1" />
      </material>
    </visual>
    <collision>
      <origin
        xyz="0 0 0"
        rpy="0 0 0" />
      <geometry>
        <mesh
          filename="package://Robot-0411-1400/meshes/Wheel_2.STL" />
      </geometry>
    </collision>
  </link>
  <joint
    name="Wheel_2"
    type="continuous">
    <origin
      xyz="-0.025708 0.14 -0.14522"
      rpy="0 0 0" />
    <parent
      link="Body" />
    <child
      link="Wheel_2" />
    <axis
      xyz="0 -1 0" />
  </joint>
</robot>