<?xml version="1.0" encoding="utf-8"?>
<!-- This URDF was automatically created by SolidWorks to URDF Exporter! Originally created by Stephen Brawner (brawner@gmail.com) 
     Commit Version: 1.6.0-4-g7f85cfe  Build Version: 1.6.7995.38578
     For more information, please see http://wiki.ros.org/sw_urdf_exporter -->
<robot
  name="lucasURDF">
  <link
    name="base_link">
    <inertial>
      <origin
        xyz="0.0030954 2.2919E-09 0.083709"
        rpy="0 0 0" />
      <mass
        value="3.9335" />
      <inertia
        ixx="0.015226"
        ixy="-4.437E-09"
        ixz="1.0651E-06"
        iyy="0.016935"
        iyz="-1.1435E-10"
        izz="0.020234" />
    </inertial>
    <visual>
      <origin
        xyz="0 0 0"
        rpy="0 0 0" />
      <geometry>
        <mesh
          filename="package://lucasURDF/meshes/base_link.STL" />
      </geometry>
      <material
        name="">
        <color
          rgba="0.69804 0.69804 0.69804 1" />
      </material>
    </visual>
    <collision>
      <origin
        xyz="0 0 0"
        rpy="0 0 0" />
      <geometry>
        <mesh
          filename="package://lucasURDF/meshes/base_link.STL" />
      </geometry>
    </collision>
  </link>
  <link
    name="thigh">
    <inertial>
      <origin
        xyz="0.1616 1.4647E-15 0.080962"
        rpy="0 0 0" />
      <mass
        value="2.4339" />
      <inertia
        ixx="0.0032145"
        ixy="-4.2463E-09"
        ixz="-0.00026107"
        iyy="0.0069314"
        iyz="5.9301E-09"
        izz="0.0041011" />
    </inertial>
    <visual>
      <origin
        xyz="0 0 0"
        rpy="0 0 0" />
      <geometry>
        <mesh
          filename="package://lucasURDF/meshes/thigh.STL" />
      </geometry>
      <material
        name="">
        <color
          rgba="0.69804 0.69804 0.69804 1" />
      </material>
    </visual>
    <collision>
      <origin
        xyz="0 0 0"
        rpy="0 0 0" />
      <geometry>
        <mesh
          filename="package://lucasURDF/meshes/thigh.STL" />
      </geometry>
    </collision>
  </link>
  <joint
    name="hip"
    type="continuous">
    <origin
      xyz="0 0 0.06"
      rpy="3.1416 0.73435 0" />
    <parent
      link="base_link" />
    <child
      link="thigh" />
    <axis
      xyz="0 1 0" />
  </joint>
  <link
    name="shin">
    <inertial>
      <origin
        xyz="0.1421 0.172 -2.7611E-05"
        rpy="0 0 0" />
      <mass
        value="1.42" />
      <inertia
        ixx="0.001417"
        ixy="2.7828E-19"
        ixz="-3.5707E-07"
        iyy="0.0038613"
        iyz="4.3486E-09"
        izz="0.0026614" />
    </inertial>
    <visual>
      <origin
        xyz="0 0 0"
        rpy="0 0 0" />
      <geometry>
        <mesh
          filename="package://lucasURDF/meshes/shin.STL" />
      </geometry>
      <material
        name="">
        <color
          rgba="0.69804 0.69804 0.69804 1" />
      </material>
    </visual>
    <collision>
      <origin
        xyz="0 0 0"
        rpy="0 0 0" />
      <geometry>
        <mesh
          filename="package://lucasURDF/meshes/shin.STL" />
      </geometry>
    </collision>
  </link>
  <joint
    name="knee"
    type="continuous">
    <origin
      xyz="0.165 -0.172 0"
      rpy="0 -1.3535 0" />
    <parent
      link="thigh" />
    <child
      link="shin" />
    <axis
      xyz="0 1 0" />
  </joint>
  <link
    name="leftwheel">
    <inertial>
      <origin
        xyz="-7.4231E-11 0.0055888 7.303E-10"
        rpy="0 0 0" />
      <mass
        value="0.31421" />
      <inertia
        ixx="0.00046114"
        ixy="-6.7334E-19"
        ixz="1.4492E-13"
        iyy="0.0008936"
        iyz="2.6066E-15"
        izz="0.00046054" />
    </inertial>
    <visual>
      <origin
        xyz="0 0 0"
        rpy="0 0 0" />
      <geometry>
        <mesh
          filename="package://lucasURDF/meshes/leftwheel.STL" />
      </geometry>
      <material
        name="">
        <color
          rgba="0.69804 0.69804 0.69804 1" />
      </material>
    </visual>
    <collision>
      <origin
        xyz="0 0 0"
        rpy="0 0 0" />
      <geometry>
        <mesh
          filename="package://lucasURDF/meshes/leftwheel.STL" />
      </geometry>
    </collision>
  </link>
  <joint
    name="leftwheel"
    type="continuous">
    <origin
      xyz="0.165 0.365 0"
      rpy="-3.1416 1.2517 0" />
    <parent
      link="shin" />
    <child
      link="leftwheel" />
    <axis
      xyz="0 1 0" />
  </joint>
  <link
    name="rightwheel">
    <inertial>
      <origin
        xyz="-6.9429E-11 0.0055888 -6.8327E-10"
        rpy="0 0 0" />
      <mass
        value="0.31421" />
      <inertia
        ixx="0.00046114"
        ixy="-4.47E-19"
        ixz="1.4497E-13"
        iyy="0.0008936"
        iyz="-2.6066E-15"
        izz="0.00046054" />
    </inertial>
    <visual>
      <origin
        xyz="0 0 0"
        rpy="0 0 0" />
      <geometry>
        <mesh
          filename="package://lucasURDF/meshes/rightwheel.STL" />
      </geometry>
      <material
        name="">
        <color
          rgba="0.69804 0.69804 0.69804 1" />
      </material>
    </visual>
    <collision>
      <origin
        xyz="0 0 0"
        rpy="0 0 0" />
      <geometry>
        <mesh
          filename="package://lucasURDF/meshes/rightwheel.STL" />
      </geometry>
    </collision>
  </link>
  <joint
    name="rightwheel"
    type="continuous">
    <origin
      xyz="0.165 -0.021 0"
      rpy="0 1.2517 0" />
    <parent
      link="shin" />
    <child
      link="rightwheel" />
    <axis
      xyz="0 1 0" />
  </joint>
</robot>