<?xml version="1.0" encoding="utf-8"?>
<!-- This URDF was automatically created by SolidWorks to URDF Exporter! Originally created by Stephen Brawner (brawner@gmail.com) 
     Commit Version: 1.6.0-4-g7f85cfe  Build Version: 1.6.7995.38578
     For more information, please see http://wiki.ros.org/sw_urdf_exporter -->
<robot
  name="lucasURDF2">
  <link
    name="head">
    <inertial>
      <origin
        xyz="0.0010918 0.015097 1.9725E-07"
        rpy="0 0 0" />
      <mass
        value="2.8477" />
      <inertia
        ixx="0.0060572"
        ixy="2.3311E-07"
        ixz="5.8494E-12"
        iyy="0.0072415"
        iyz="-7.9595E-09"
        izz="0.0087327" />
    </inertial>
    <visual>
      <origin
        xyz="0 0 0"
        rpy="0 0 0" />
      <geometry>
        <mesh
          filename="package://lucasURDF2/meshes/head.STL" />
      </geometry>
      <material
        name="">
        <color
          rgba="0.69804 0.69804 0.69804 1" />
      </material>
    </visual>
    <collision>
      <origin
        xyz="0 0 0"
        rpy="0 0 0" />
      <geometry>
        <mesh
          filename="package://lucasURDF2/meshes/head.STL" />
      </geometry>
    </collision>
  </link>
  <joint
    name="leftmotor"
    type="continuous">
    <origin
      xyz="0.165 0.148 0"
      rpy="0 -0.56647 3.1416" />
    <parent
      link="shin" />
    <child
      link="leftwheel" />
    <axis
      xyz="0 1 0" />
  </joint>
  <link
    name="thigh">
    <inertial>
      <origin
        xyz="0.12618 2.5582E-17 2.5187E-05"
        rpy="0 0 0" />
      <mass
        value="0.77836" />
      <inertia
        ixx="0.00048762"
        ixy="9.7886E-20"
        ixz="6.461E-07"
        iyy="0.0020039"
        iyz="2.9122E-09"
        izz="0.0016631" />
    </inertial>
    <visual>
      <origin
        xyz="0 0 0"
        rpy="0 0 0" />
      <geometry>
        <mesh
          filename="package://lucasURDF2/meshes/thigh.STL" />
      </geometry>
      <material
        name="">
        <color
          rgba="0.69804 0.69804 0.69804 1" />
      </material>
    </visual>
    <collision>
      <origin
        xyz="0 0 0"
        rpy="0 0 0" />
      <geometry>
        <mesh
          filename="package://lucasURDF2/meshes/thigh.STL" />
      </geometry>
    </collision>
  </link>
  <joint
    name="hip"
    type="continuous">
    <origin
      xyz="0 0 -0.025"
      rpy="3.1416 0.7279 0" />
    <parent
      link="head" />
    <child
      link="thigh" />
    <axis
      xyz="0 1 0" />
  </joint>
  <link
    name="shin">
    <inertial>
      <origin
        xyz="0.12392 1.7531E-17 -4.9529E-05"
        rpy="0 0 0" />
      <mass
        value="0.79162" />
      <inertia
        ixx="0.00049577"
        ixy="-5.8702E-20"
        ixz="1.2197E-18"
        iyy="0.0020741"
        iyz="4.3486E-09"
        izz="0.0017393" />
    </inertial>
    <visual>
      <origin
        xyz="0 0 0"
        rpy="0 0 0" />
      <geometry>
        <mesh
          filename="package://lucasURDF2/meshes/shin.STL" />
      </geometry>
      <material
        name="">
        <color
          rgba="0.69804 0.69804 0.69804 1" />
      </material>
    </visual>
    <collision>
      <origin
        xyz="0 0 0"
        rpy="0 0 0" />
      <geometry>
        <mesh
          filename="package://lucasURDF2/meshes/shin.STL" />
      </geometry>
    </collision>
  </link>
  <joint
    name="knee"
    type="continuous">
    <origin
      xyz="0.165 0 0"
      rpy="-3.1416 -1.5176 3.1416" />
    <parent
      link="thigh" />
    <child
      link="shin" />
    <axis
      xyz="0 1 0" />
  </joint>
  <link
    name="rightwheel">
    <inertial>
      <origin
        xyz="-4.6667E-12 -0.029411 -1.4181E-11"
        rpy="0 0 0" />
      <mass
        value="0.18329" />
      <inertia
        ixx="0.000269"
        ixy="-8.7101E-19"
        ixz="8.4555E-14"
        iyy="0.00052127"
        iyz="-1.5208E-15"
        izz="0.00026865" />
    </inertial>
    <visual>
      <origin
        xyz="0 0 0"
        rpy="0 0 0" />
      <geometry>
        <mesh
          filename="package://lucasURDF2/meshes/rightwheel.STL" />
      </geometry>
      <material
        name="">
        <color
          rgba="0.69804 0.69804 0.69804 1" />
      </material>
    </visual>
    <collision>
      <origin
        xyz="0 0 0"
        rpy="0 0 0" />
      <geometry>
        <mesh
          filename="package://lucasURDF2/meshes/rightwheel.STL" />
      </geometry>
    </collision>
  </link>
  <joint
    name="rightmotor"
    type="continuous">
    <origin
      xyz="0.165 -0.148 0"
      rpy="-3.1416 -0.56647 -3.1416" />
    <parent
      link="shin" />
    <child
      link="rightwheel" />
    <axis
      xyz="0 1 0" />
  </joint>
  <link
    name="leftwheel">
    <inertial>
      <origin
        xyz="-1.1102E-16 -0.029411 3.4779E-12"
        rpy="0 0 0" />
      <mass
        value="0.18329" />
      <inertia
        ixx="0.000269"
        ixy="-9.0806E-19"
        ixz="8.4555E-14"
        iyy="0.00052127"
        iyz="1.5208E-15"
        izz="0.00026865" />
    </inertial>
    <visual>
      <origin
        xyz="0 0 0"
        rpy="0 0 0" />
      <geometry>
        <mesh
          filename="package://lucasURDF2/meshes/leftwheel.STL" />
      </geometry>
      <material
        name="">
        <color
          rgba="0.69804 0.69804 0.69804 1" />
      </material>
    </visual>
    <collision>
      <origin
        xyz="0 0 0"
        rpy="0 0 0" />
      <geometry>
        <mesh
          filename="package://lucasURDF2/meshes/leftwheel.STL" />
      </geometry>
    </collision>
  </link>
  <joint
    name="leftmotor"
    type="continuous">
    <origin
      xyz="0.165 0.148 0"
      rpy="0 -0.56647 3.1416" />
    <parent
      link="shin" />
    <child
      link="leftwheel" />
    <axis
      xyz="0 1 0" />
  </joint>
</robot>