<?xml version="1.0" encoding="utf-8"?>
<!-- This URDF was automatically created by SolidWorks to URDF Exporter! Originally created by Stephen Brawner (brawner@gmail.com) 
     Commit Version: 1.6.0-4-g7f85cfe  Build Version: 1.6.7995.38578
     For more information, please see http://wiki.ros.org/sw_urdf_exporter -->
<robot
  name="robot_description">
  <link
    name="Body">
    <inertial>
      <origin
        xyz="-0.00122823958383303 4.16333634234434E-17 0.111919104535524"
        rpy="0 0 0" />
      <mass
        value="0.259687822807211" />
      <inertia
        ixx="0.000263883767567918"
        ixy="1.04528591301818E-19"
        ixz="2.83874959864717E-05"
        iyy="0.00029022151243818"
        iyz="-1.15373324614303E-19"
        izz="0.000304338639837751" />
    </inertial>
    <visual>
      <origin
        xyz="0 0 0"
        rpy="0 0 0" />
      <geometry>
        <mesh
          filename="package://robot_description/meshes/Body.STL" />
      </geometry>
      <material
        name="">
        <color
          rgba="0.792156862745098 0.819607843137255 0.933333333333333 1" />
      </material>
    </visual>
    <collision>
      <origin
        xyz="0 0 0"
        rpy="0 0 0" />
      <geometry>
        <mesh
          filename="package://robot_description/meshes/Body.STL" />
      </geometry>
    </collision>
  </link>
  <link
    name="Wheel_1">
    <inertial>
      <origin
        xyz="-3.53883589099269E-16 3.43013075544458E-17 6.66133814775094E-16"
        rpy="0 0 0" />
      <mass
        value="0.0981527452118754" />
      <inertia
        ixx="7.13246475399758E-05"
        ixy="-1.0128527790249E-20"
        ixz="4.9595293836236E-20"
        iyy="0.00013687545343136"
        iyz="3.05631062116939E-21"
        izz="7.13246475399756E-05" />
    </inertial>
    <visual>
      <origin
        xyz="0 0 0"
        rpy="0 0 0" />
      <geometry>
        <mesh
          filename="package://robot_description/meshes/Wheel_1.STL" />
      </geometry>
      <material
        name="">
        <color
          rgba="0.792156862745098 0.819607843137255 0.933333333333333 1" />
      </material>
    </visual>
    <collision>
      <origin
        xyz="0 0 0"
        rpy="0 0 0" />
      <geometry>
        <mesh
          filename="package://robot_description/meshes/Wheel_1.STL" />
      </geometry>
    </collision>
  </link>
  <joint
    name="Wheel_1"
    type="continuous">
    <origin
      xyz="0 -0.075 0"
      rpy="0 0 0" />
    <parent
      link="Body" />
    <child
      link="Wheel_1" />
    <axis
      xyz="0 -1 0" />
  </joint>
  <link
    name="Wheel_2">
    <inertial>
      <origin
        xyz="5.06539254985228E-16 0.01 6.66133814775094E-16"
        rpy="0 0 0" />
      <mass
        value="0.0981527452118754" />
      <inertia
        ixx="7.13246475399757E-05"
        ixy="1.1312674562977E-20"
        ixz="4.9475740388328E-20"
        iyy="0.00013687545343136"
        iyz="-2.9293753358638E-21"
        izz="7.13246475399756E-05" />
    </inertial>
    <visual>
      <origin
        xyz="0 0 0"
        rpy="0 0 0" />
      <geometry>
        <mesh
          filename="package://robot_description/meshes/Wheel_2.STL" />
      </geometry>
      <material
        name="">
        <color
          rgba="0.792156862745098 0.819607843137255 0.933333333333333 1" />
      </material>
    </visual>
    <collision>
      <origin
        xyz="0 0 0"
        rpy="0 0 0" />
      <geometry>
        <mesh
          filename="package://robot_description/meshes/Wheel_2.STL" />
      </geometry>
    </collision>
  </link>
  <joint
    name="Wheel_2"
    type="continuous">
    <origin
      xyz="0 0.065 0"
      rpy="0 0 0" />
    <parent
      link="Body" />
    <child
      link="Wheel_2" />
    <axis
      xyz="0 -1 0" />
  </joint>
</robot>